<?xml version="1.0"?>
<sdf version="1.5">
<model name = "arm">

<link name="Bottom">

<pose>0.0855 -0.12 -0.115 0 0 0</pose>

<inertial>
<pose> 0.12 0.07 0.16 0 0 0</pose>
<mass> 0.15502294</mass>
<inertia>
<ixx>0.00016521</ixx>
<iyy>0.00074812</iyy>
<izz>0.00087562</izz>
<ixy>-0.00008580</ixy>
<ixz>0.00000674</ixz>
<iyz>-0.00000277</iyz>
</inertia>
</inertial>

<collision name="Bottom_collision">
<pose> 0 0.125 0.14 1.5708 0 0 </pose>
<geometry>
<mesh>
<uri>model://MovableGripper/meshes/BottomMock.dae</uri>
</mesh>
</geometry>
</collision>

<visual name="Bottom_visual">
<geometry>
<mesh>
<uri>model://MovableGripper/meshes/BottomMock.dae</uri>
</mesh>
</geometry>
</visual>

</link>

<link name="Top">

<pose>0.2695 -0.119 -0.115 0 0 0</pose>

<inertial>
<pose> 0.115 0.07 0.16 0 0 0</pose>
<mass> 0.12067183</mass>
<inertia>
<ixx>0.00017544</ixx>
<iyy>0.00057466</iyy>
<izz>0.00065738</izz>
<ixy>-0.00009377</ixy>
<ixz>0.00009018</ixz>
<iyz>-0.00004054</iyz>
</inertia>
</inertial>

<collision name="Top_collision">
<geometry>
<mesh>
<uri>model://MovableGripper/meshes/top.dae</uri>
</mesh>
</geometry>
</collision>

<visual name="Top_visual">
<geometry>
<mesh>
<uri>model://MovableGripper/meshes/top.dae</uri>
</mesh>
</geometry>
</visual>

</link>

<link name="GripperBase">

<pose>0.012 0.0025 0.03 1.5708 0 0</pose>

<inertial>
<pose> 0 0 0 0 0 0</pose>
<mass> 0.12067183</mass>
<inertia>
<ixx>0.00017544</ixx>
<iyy>0.00057466</iyy>
<izz>0.00065738</izz>
<ixy>-0.00009377</ixy>
<ixz>0.00009018</ixz>
<iyz>-0.00004054</iyz>
</inertia>
</inertial>

<collision name="GripperBase_collision">
<geometry>
<mesh>
<uri>model://MovableGripper/meshes/GripperBase.dae</uri>
</mesh>
</geometry>
</collision>

<visual name="GripperBase_visual">
<geometry>
<mesh>
<uri>model://MovableGripper/meshes/GripperBase.dae</uri>
</mesh>
</geometry>
</visual>

</link>

<link name="GripperArm">

<pose>0.016 0.0027 0.048 1.5708 0 0</pose>

<inertial>
<pose> 0 0 0 0 0 0</pose>
<mass> 0.12067183</mass>
<inertia>
<ixx>0.00017544</ixx>
<iyy>0.00057466</iyy>
<izz>0.00065738</izz>
<ixy>-0.00009377</ixy>
<ixz>0.00009018</ixz>
<iyz>-0.00004054</iyz>
</inertia>
</inertial>

<collision name="GripperArm_collision">
<geometry>
<mesh>
<uri>model://MovableGripper/meshes/GripperArm.dae</uri>
</mesh>
</geometry>
</collision>

<visual name="GripperArm_visual">
<geometry>
<mesh>
<uri>model://MovableGripper/meshes/GripperArm.dae</uri>
</mesh>
</geometry>
</visual>

</link>

<link name="FrontArm">

<pose>0.0545 0.4575 0.217 1.5708 0 -1.5708</pose>

<inertial>
<pose> 0 0 0 0 0 0</pose>
<mass> 0.12067183</mass>
<inertia>
<ixx>0.00017544</ixx>
<iyy>0.00057466</iyy>
<izz>0.00065738</izz>
<ixy>-0.00009377</ixy>
<ixz>0.00009018</ixz>
<iyz>-0.00004054</iyz>
</inertia>
</inertial>

<collision name="Front_collision">
<geometry>
<mesh>
<uri>model://MovableGripper/meshes/FrontArm.dae</uri>
</mesh>
</geometry>
</collision>

<visual name="FrontArm_visual">
<geometry>
<mesh>
<uri>model://MovableGripper/meshes/FrontArm.dae</uri>
</mesh>
</geometry>
</visual>

</link>

<joint name = "Arm_joint" type="revolute">

<pose>0.017 0.065 0.1675 0 0 0</pose>
<child>Top</child>
<parent>Bottom</parent>
<axis>
<limit>
<upper>3.141526</upper>
<lower>0</lower>
</limit>
<xyz>0 1 0</xyz>
</axis>
</joint>

<joint name = "Gripper_stationary_joint" type="revolute">

<pose>0 0 0 0 0 0</pose>
<child>GripperBase</child>
<parent>Bottom</parent>
<axis>
<limit>
<upper>0</upper>
<lower>0</lower>
</limit>
<xyz>0 0 1</xyz>
</axis>
</joint>

<joint name = "Gripper_arm_joint" type="revolute">

<pose>0.068 0.01 0.07 0 0 0</pose>
<child>GripperArm</child>
<parent>GripperBase</parent>
<axis>
<limit>
<upper>0</upper>
<lower>-1.5708</lower>
</limit>
<xyz>0 0 1</xyz>
</axis>
</joint>

<joint name = "Front_arm_joint" type="revolute">

<pose>0.557 -0.159 0.0065 0 0 0</pose>
<child>FrontArm</child>
<parent>GripperBase</parent>
<axis>
<limit>
<upper>0</upper>
<lower>-1.5708</lower>
</limit>
<xyz>0 0 1</xyz>
</axis>
</joint>

<self_collide>false</self_collide>
</model>
</sdf>

