<?xml version="1.0"?>
<sdf version="1.5">
<model name = "arm">

<link name="Bottom">

<pose>0.0855 -0.12 -0.115 0 0 0</pose>

<inertial>
<pose> 0.105 0.079 0.165 0 0 0</pose>
<mass> 0.03251090</mass>
<inertia>
<ixx>0.00000957</ixx>
<iyy>0.00011708</iyy>
<izz>0.00012190</izz>
<ixy>0.00000092</ixy>
<ixz>-0.00000366</ixz>
<iyz>-0.00000004</iyz>
</inertia>
</inertial>

<collision name="Bottom_collision">
<pose> 0 0.125 0.14 1.5708 0 0 </pose>
<geometry>
<mesh>
<uri>model://MovableGripper/meshes/BottomMock.dae</uri>
</mesh>
</geometry>
</collision>

<visual name="Bottom_visual">
<geometry>
<mesh>
<uri>model://MovableGripper/meshes/BottomMock.dae</uri>
</mesh>
</geometry>
</visual>

</link>

<link name="Top">

<pose>0.2695 -0.119 -0.115 0 0 0</pose>

<inertial>
<pose> 0.115 0.0925 0.16 0 0 0</pose>
<mass> 0.12067183</mass>
<inertia>
<ixx>0.00017544</ixx>
<iyy>0.00057466</iyy>
<izz>0.00065738</izz>
<ixy>-0.00009377</ixy>
<ixz>0.00009018</ixz>
<iyz>-0.00004054</iyz>
</inertia>
</inertial>

<collision name="Top_collision">
<geometry>
<mesh>
<uri>model://MovableGripper/meshes/top.dae</uri>
</mesh>
</geometry>
</collision>

<visual name="Top_visual">
<geometry>
<mesh>
<uri>model://MovableGripper/meshes/top.dae</uri>
</mesh>
</geometry>
</visual>

</link>

<link name="GripperBase">

<pose>0.012 0.0025 0.03 1.5708 0 0</pose>

<inertial>
<pose> 0.049 0.023 0.034 0 1.5708 0</pose>
<mass> 0.195</mass>
<inertia>
<ixx>0.00023607</ixx>
<iyy>0.00034643</iyy>
<izz>0.00015122</izz>
<ixy>0.00000945</ixy>
<ixz>0.00001664</ixz>
<iyz>0.00000758</iyz>
</inertia>
</inertial>

<collision name="GripperBase_collision">
<geometry>
<mesh>
<uri>model://MovableGripper/meshes/GripperBase.dae</uri>
</mesh>
</geometry>
</collision>

<visual name="GripperBase_visual">
<geometry>
<mesh>
<uri>model://MovableGripper/meshes/GripperBase.dae</uri>
</mesh>
</geometry>
</visual>

</link>

<link name="GripperArm">

<pose>0.016 0.0027 0.048 1.5708 0 0</pose>

<inertial>
<pose> 0.03 0.02 0.035 0 1.5708 0</pose>
<mass> 0.0256372</mass>
<inertia>
<ixx>0.00001361</ixx>
<iyy>0.00002058</iyy>
<izz>0.00000766</izz>
<ixy>0.00000062</ixy>
<ixz>0.00000175</ixz>
<iyz>0.00000022</iyz>
</inertia>
</inertial>

<collision name="GripperArm_collision">
<geometry>
<mesh>
<uri>model://MovableGripper/meshes/GripperArm.dae</uri>
</mesh>
</geometry>
</collision>

<visual name="GripperArm_visual">
<geometry>
<mesh>
<uri>model://MovableGripper/meshes/GripperArm.dae</uri>
</mesh>
</geometry>
</visual>

</link>

<link name="FrontArm">

<pose>0.0545 0.4575 0.217 1.5708 0 -1.5708</pose>

<inertial>
<pose> 0.51 -0.155 0.022 0 0 0</pose>
<mass> 0.00983358</mass>
<inertia>
<ixx>0.00000270</ixx>
<iyy>0.00001009</iyy>
<izz>0.00000795</izz>
<ixy>-0.00000021</ixy>
<ixz>-0.00000344</ixz>
<iyz>0.00000014</iyz>
</inertia>
</inertial>

<collision name="Front_collision">
<geometry>
<mesh>
<uri>model://MovableGripper/meshes/FrontArm.dae</uri>
</mesh>
</geometry>
</collision>

<visual name="FrontArm_visual">
<geometry>
<mesh>
<uri>model://MovableGripper/meshes/FrontArm.dae</uri>
</mesh>
</geometry>
</visual>

</link>

<joint name = "Arm_joint" type="revolute">

<pose>0.017 0.065 0.1675 0 0 0</pose>
<child>Top</child>
<parent>Bottom</parent>
<axis>
<limit>
<upper>3.141526</upper>
<lower>0</lower>
</limit>
<xyz>0 1 0</xyz>
</axis>
</joint>

<joint name = "Gripper_stationary_joint" type="revolute">

<pose>0 0 0 0 0 0</pose>
<child>GripperBase</child>
<parent>Bottom</parent>
<axis>
<limit>
<upper>0</upper>
<lower>0</lower>
</limit>
<xyz>0 0 1</xyz>
</axis>
</joint>

<joint name = "Gripper_arm_joint" type="revolute">

<pose>0.068 0.01 0.07 0 0 0</pose>
<child>GripperArm</child>
<parent>GripperBase</parent>
<axis>
<limit>
<upper>0</upper>
<lower>-1.5708</lower>
</limit>
<xyz>0 0 1</xyz>
</axis>
</joint>

<joint name = "Front_arm_joint" type="revolute">

<pose>0.557 -0.159 0.0065 0 0 0</pose>
<child>FrontArm</child>
<parent>GripperBase</parent>
<axis>
<limit>
<upper>0</upper>
<lower>-1.5708</lower>
</limit>
<xyz>0 0 1</xyz>
</axis>
</joint>

<self_collide>false</self_collide>
</model>
</sdf>

