<?xml version="1.0"?>
<sdf version="1.5">
<model name = "PhytobiopsyAssembly">

<link name="Bottom">

<pose>0 -0.12 -0.11 0 0 0</pose>

<inertial>
<pose> 0.12 0.07 0.16 0 0 0</pose>
<mass> 0.22751</mass>
<inertia>
<ixx>0.00023475543</ixx>
<iyy>0.00073669092</iyy>
<izz>0.00092412105</izz>
<ixy>0.00000364703</ixy>
<ixz>0.00000048495</ixz>
<iyz>-0.00000315664</iyz>
</inertia>
</inertial>

<collision name="Bottom_collision">
<pose> 0 0.125 0.14 1.5708 0 0 </pose>
<geometry>
<mesh>
<uri>model://PhytobiopsyAssembly/meshes/mock_bottom.dae</uri>
</mesh>
</geometry>
</collision>

<visual name="Bottom_visual">
<geometry>
<mesh>
<uri>model://PhytobiopsyAssembly/meshes/bottom.dae</uri>
</mesh>
</geometry>
</visual>

</link>

<link name="Top">

<pose>0.2695 -0.119 -0.115 0 0 0</pose>

<inertial>
<pose> 0.115 0.07 0.16 0 0 0</pose>
<mass> 0.15684</mass>
<inertia>
<ixx>0.00019529778</ixx>
<iyy>0.00124753983</iyy>
<izz>0.00134322318</izz>
<ixy>-0.00019292875</ixy>
<ixz>0.00013226436</ixz>
<iyz>-0.00004812716</iyz>
</inertia>
</inertial>

<collision name="Top_collision">
<geometry>
<mesh>
<uri>model://PhytobiopsyAssembly/meshes/top.dae</uri>
</mesh>
</geometry>
</collision>

<visual name="Top_visual">
<geometry>
<mesh>
<uri>model://PhytobiopsyAssembly/meshes/top.dae</uri>
</mesh>
</geometry>
</visual>

</link>

<joint name = "Arm_joint" type="revolute">

<pose>0.0175 0.065 0.1675 0 0 0</pose>
<child>Top</child>
<parent>Bottom</parent>
<axis>
<limit>
<upper>0</upper>
<lower>-3.141526</lower>
</limit>
<xyz>0 1 0</xyz>
<dynamics>
<friction>0.01</friction>
<damping>0.015</damping>
</dynamics>
</axis>
</joint>


<self_collide>true</self_collide>
</model>
</sdf>

