<?xml version="1.0" ?>
<sdf version="1.5">
  <model name="tree_model">
	<pose>0 0 0.125 0 0 0</pose>
	<static>false</static>
	<self_collide>true</self_collide>
	<link name = "stationary">
		<inertial>
		<mass>10</mass>
        	<inertia>
          	<ixx>0.056</ixx>
          	<ixy>0</ixy>
          	<ixz>0</ixz>
          	<iyy>0.056</iyy>
          	<iyz>0</iyz>
          	<izz>0.008</izz>
        	</inertia>
      	</inertial>
	<visual name="stationary_visual">
		<geometry>
		<cylinder>
		<radius>0.05</radius>
		<length>0.25</length>
		</cylinder>
		</geometry>
	</visual>
        <collision name="stationary_collision">
                <geometry>
                <cylinder>
                <radius>0.05</radius>
                <length>0.25</length>
                </cylinder>
		</geometry>
        </collision>
	</link>

       <link name = "branch1">
		<pose> 0.130 0 0.424 0 0.5236 0 </pose> 
                <inertial>
                <mass>0.1</mass>
                <inertia>
                <ixx>0.0030225</ixx>
                <ixy>0</ixy>
                <ixz>0</ixz>
                <iyy>0.0030225</iyy>
                <iyz>0</iyz>
                <izz>0.000045</izz>
                </inertia>
        </inertial>
        <visual name="branch1_visual">
                <geometry>
                <cylinder>
                <radius>0.03</radius>
                <length>0.6</length>
                </cylinder>
                </geometry>
        </visual>
        <collision name="branch1_collision">
                <geometry>
                <cylinder>
                <radius>0.03</radius>
                <length>0.6</length>
                </cylinder>
                </geometry>
        </collision>
        </link>

       <link name = "branch2">
                <pose> 0.346 0 0.91 0 0.2618 0 </pose>
                <inertial>
                <mass>0.07</mass>
                <inertia>
                <ixx>0.00171</ixx>
                <ixy>0</ixy>
                <ixz>0</ixz>
                <iyy>0.00171</iyy>
                <iyz>0</iyz>
                <izz>0.000045</izz>
                </inertia>
        </inertial>
        <visual name="branch2_visual">
                <geometry>
                <cylinder>
                <radius>0.03</radius>
                <length>0.45</length>
                </cylinder>
                </geometry>
        </visual>
        <collision name="branch2_collision">
                <geometry>
                <cylinder>
                <radius>0.03</radius>
                <length>0.6</length>
                </cylinder>
                </geometry>
        </collision>
        </link>

        <joint name="branch2_joint" type="revolute">
        <parent>branch2</parent>
        <child>branch1</child>
        <axis>
                <xyz>0 1 0</xyz>
                <dynamics>
                <damping>0.2</damping>
                <spring_reference>0</spring_reference>
                <spring_stiffness>2.35</spring_stiffness>
                </dynamics>
        </axis>
        </joint>

	<joint name="branch1_joint" type="revolute">
	<parent>branch1</parent>
	<child>stationary</child>
	<axis>
		<xyz>0 1 0</xyz>
		<dynamics>
		<damping>0.26</damping>
		<spring_reference>0</spring_reference>
		<spring_stiffness>3.8</spring_stiffness>
		</dynamics>
	</axis>
	</joint>
  </model>
</sdf>
